Workbook
Name ___________________________________b1: {"annual",#N/A,FALSE,"Pro Forma";#N/A,#N/A,FALSE,"Golf Operations"}
Name ___________________________________b1: {"annual",#N/A,FALSE,"Pro Forma";#N/A,#N/A,FALSE,"Golf Operations"}
Name ___________________________________b1: {"annual",#N/A,FALSE,"Pro Forma";#N/A,#N/A,FALSE,"Golf Operations"}
Name ___________________________________b1: {"annual",#N/A,FALSE,"Pro Forma";#N/A,#N/A,FALSE,"Golf Operations"}
Name ___________________________________b1: {"annual",#N/A,FALSE,"Pro Forma";#N/A,#N/A,FALSE,"Golf Operations"}
Name ___________________________________cd1: {"annual",#N/A,FALSE,"Pro Forma";#N/A,#N/A,FALSE,"Golf Operations"}
Name ___________________________________cd1: {"annual",#N/A,FALSE,"Pro Forma";#N/A,#N/A,FALSE,"Golf Operations"}
Name ___________________________________cd1: {"annual",#N/A,FALSE,"Pro Forma";#N/A,#N/A,FALSE,"Golf Operations"}
Name ___________________________________cd1: {"annual",#N/A,FALSE,"Pro Forma";#N/A,#N/A,FALSE,"Golf Operations"}
Name ___________________________________cd1: {"annual",#N/A,FALSE,"Pro Forma";#N/A,#N/A,FALSE,"Golf Operations"}
Name ___________________________________gr1: {"three",#N/A,FALSE,"Capital";"four",#N/A,FALSE,"Capital"}
Name ___________________________________gr1: {"three",#N/A,FALSE,"Capital";"four",#N/A,FALSE,"Capital"}
Name ___________________________________gr1: {"three",#N/A,FALSE,"Capital";"four",#N/A,FALSE,"Capital"}
Name ___________________________________gr1: {"three",#N/A,FALSE,"Capital";"four",#N/A,FALSE,"Capital"}
Name ___________________________________gr1: {"three",#N/A,FALSE,"Capital";"four",#N/A,FALSE,"Capital"}
Name ___________________________________wr1: {"Output-3Column",#N/A,FALSE,"Output"}
Name ___________________________________wr1: {"Output-3Column",#N/A,FALSE,"Output"}
Name ___________________________________wr1: {"Output-3Column",#N/A,FALSE,"Output"}
Name ___________________________________wr1: {"Output-3Column",#N/A,FALSE,"Output"}
Name ___________________________________wr1: {"Output-3Column",#N/A,FALSE,"Output"}
Name ___________________________________wrn1: {"Inflation-BaseYear",#N/A,FALSE,"Inputs"}
Name ___________________________________wrn1: {"Inflation-BaseYear",#N/A,FALSE,"Inputs"}
Name ___________________________________wrn1: {"Inflation-BaseYear",#N/A,FALSE,"Inputs"}
Name ___________________________________wrn1: {"Inflation-BaseYear",#N/A,FALSE,"Inputs"}
Name ___________________________________wrn1: {"Inflation-BaseYear",#N/A,FALSE,"Inputs"}
Name ___________________________________wrn4: {"data",#N/A,FALSE,"INPUT"}
Name ___________________________________wrn4: {"data",#N/A,FALSE,"INPUT"}
Name ___________________________________wrn4: {"data",#N/A,FALSE,"INPUT"}
Name ___________________________________wrn4: {"data",#N/A,FALSE,"INPUT"}
Name ___________________________________wrn4: {"data",#N/A,FALSE,"INPUT"}
Name _______ACA1: #REF!
Name _______ACA2: #N/A
Name _______ADD1: #REF!
Name _______ADD2: #REF!
Name _______ADD3: #REF!
Name _______ADD4: #REF!
Name _______ADD5: #REF!
Name _______ADD6: #REF!
Name _______ADD7: #REF!
Name _______CPV2: #REF!
Name _______CPV3: #REF!
Name _______dec1: #REF!
Name _______Div10: #REF!
Name _______Div11: #REF!
Name _______Div12: #REF!
Name _______Div13: #REF!
Name _______Div14: #REF!
Name _______Div15: #REF!
Name _______Div16: #REF!
Name _______Div19: #REF!
Name _______Div2: #REF!
Name _______Div3: #REF!
Name _______Div4: #REF!
Name _______Div5: #REF!
Name _______Div6: #REF!
Name _______Div7: #REF!
Name _______Div8: #REF!
Name _______Div9: #REF!
Name _______fgv1: #REF!
Name _______fgv2: #REF!

Sheet GUIDE
A1: LONG-RANGE FINANCIAL PROJECTION TEMPLATE | E1: REQUIRES "ITERATIVE CALCULATIONS" TO BE ENABLED
A2: Washington State Charter School Commission | MODEL GUIDE
A3: in service of quality authorizing in the State of Washington
A5: PURPOSE OF THIS MODEL
A6: The Long-Range Projection (LRP) Model is a multi-year financial planning tool designed to help Washington State charter schools and their authorizer:
B7: → Understand long-term financial sustainability across a 5-year projection horizon
B8: → Evaluate how enrollment growth, grade-span expansion, and staffing decisions affect fiscal health
B9: → Estimate state revenues under WA apportionment formulas (BEA, Special Education, LAP, TBIP)
B10: → Assess facility financing scenarios and debt affordability
B11: → Identify key financial risks, cash flow vulnerabilities, and trade-offs
B12: → Support Board-level strategic decision making and authorizer financial review
A14: This model is not a budget. It is a scenario planning tool that shows what must be true for a charter school to remain financially stable over time.
A16: WA-Specific Context: Washington charter schools receive state apportionment from OSPI based on AAFTE enrollment, not headcount.
A17: Unlike school districts, charter schools cannot levy local property taxes and do not receive dedicated facilities funding from the state.
A18: This model reflects those structural constraints throughout
A20: HOW TO USE THIS MODEL
A21: STEP 1 | C21: Enter School Information
C22: Go to the INPUTS tab. Enter school name, city, zip, district number, grade span, fiscal contact, and beginning fiscal year. This information populates headers across the model.
A23: STEP 2 | C23: Enter Planned Enrollment
C24: Go to the ENROLLMENT tab. Enter AAFTE enrollment by grade level and year for your Planned scenario. WA apportionment is based on Annual Average Full-Time Equivalent (AAFTE), not headcount. Set your Sensitivity scenario percentage in INPUTS (default: 90% of planned).
A25: STEP 3 | C25: Set the Active Enrollment Scenario
C26: Return to INPUTS and select which enrollment scenario to model: Planned or Sensitivity. All revenue, staffing, and financial projections will update automatically based on your selection.
A27: STEP 4 | C27: Review and Adjust Revenue Assumptions
C28: Go to the REVENUE section of the INPUTS tab. Confirm per-pupil rate assumptions for General Apportionment (BEA), Special Education, LAP, TBIP, and other state categoricals. Update annual COLA growth rates in INPUTS. Adjust student needs percentages (SPED %, FRPL %, EL %) to match your population in ENROLLMENT
A29: STEP 5 | C29: Review and Adjust Staffing
C30: Go to Section 3 in the INPUTS tab. Position types and benefits %s have been pre-loaded, adjust to match your school's staffing plan. Go to the STAFFING tab. Review FTE ratios and average salary assumptions by position type. Adjust to match your school's staffing plan. Salary benchmarks are pre-loaded from OSPI and BLS Washington data.
A31: STEP 6 | C31: Enter Financing Assumptions (if applicable)
C32: Go to the DEBT tab. Enter facility borrowing scenarios including par amount, interest rate, term, and closing date. The model calculates annual debt service and integrates it into the P&L and Cash projections.
A33: STEP 7 | C33: Review Financial Results
C34: Review the P&L tab for multi-year operating projections. Review the Cash tab for monthly cash flow, disbursement timing, and days of cash on hand.
A35: STEP 8 | C35: Review Summary Reports
C36: The REPORTS tab provides high-level dashboards, per-pupil metrics, financial health indicators, and visuals for Board presentation and authorizer financial review.
A38: MODEL STRUCTURE & FLOW of INFORMATION
A39: TAB COLOR
B40: YELLOW INPUT TABS | E40: KEY INPUTS/OUTPUTS
C41: INPUTS | D41: Primary inputs: school info, revenue per-pupil rates, growth rates, expense inflation, beginning cash balance, and enrollment scenario selection. | E41: School profile · BEA rate · COLA % · SpEd % · FRPL % · EL %
C42: ENROLLMENT | D42: AAFTE enrollment by grade level and year. Two parallel scenarios: Planned projection and Sensitivity analysis (% of planned). | E42: Grade-by-grade AAFTE · Total enrollment · Sensitivity scenario
C43: REVENUE (now a section in INPUTS) | D43: State & Local revenue calculations. Estimates per-pupil revenue for General Apportionment (BEA), Special Education, LAP, TBIP, and other categoricals based on enrollment and rate assumptions. | E43: Rev. by source · Per-pupil rates · Student population weights
C44: STAFFING | D44: Staffing ratios, FTE counts by position type, and average salary assumptions. Pre-loaded with WA wage benchmarks from OSPI and BLS. | E44: FTE by position · Avg salary · Student-to-staff ratios
C45: DEBT | D45: Facility financing inputs: par amount, interest rate, amortization term, closing date. Produces annual debt service schedule. | E45: Loan amount · Rate · Term · Annual principal & interest
...

Sheet INPUTS
A1: PRIMARY INPUTS | D1: =C4 -> 2027 | E1: =D1+1 -> 2028 | F1: =E1+1 -> 2029 | G1: =F1+1 -> 2030 | H1: =G1+1 -> 2031 | I1: =H1+1 -> 2032 | J1: NOTES
B3: School Name: | C3: Cedar Grove Public Schools
B4: Beginning Fiscal Year (Year 0): | C4: 2027
B6: School Fiscal Contact Name: | C6: Melissa Pettey
B7: School Fiscal Contact Email: | C7: petteymelissa1@gmail.com
B8: School Fiscal Contact Phone: | C8: (509) 953-2320
B10: School Audit Firm Name: | C10: [Audit Firm Name]
B11: School Audit Contact Name: | C11: [First and Last Name]
B12: School Audit Contact Email: | C12: xxxxx@xxxxx.xxx
B13: School Audit Contact Phone: | C13: 555.555.5555 ext. 456
C15: ENROLLMENT LINK
C17: Planned | D17: {=_xlfn.IFS(C17="Planned", 1, C17="Sensitivity Analysis", 2)} -> 1
A19: SECTION 1: REVENUE
B21: Year 0 Beginning Cash Balance | C21: 1250000
B23: PER PUPIL REVENUE GROWTH RATES
B25: Description | C25: Driver | D25: =$D$1 -> 2027 | E25: =$E$1 -> 2028 | F25: =$F$1 -> 2029 | G25: =$G$1 -> 2030 | H25: =$H$1 -> 2031 | I25: =$I$1 -> 2032
B26: State Revenue | D26: 0.025 | E26: 0.025 | F26: 0.025 | G26: 0.025 | H26: 0.025 | I26: 0.025
B27: Federal Revenue | D27: 0.015 | E27: 0.015 | F27: 0.015 | G27: 0.015 | H27: 0.015 | I27: 0.015
B28: Local / Other | D28: 0.025 | E28: 0.025 | F28: 0.025 | G28: 0.025 | H28: 0.025 | I28: 0.025
B30: Interest earned on cash balances | C30: 0.03
B32: REVENUES | C32: Driver | D32: =$D$1 -> 2027 | E32: =$E$1 -> 2028 | F32: =$F$1 -> 2029 | G32: =$G$1 -> 2030 | H32: =$H$1 -> 2031 | I32: =$I$1 -> 2032 | J32: Recurring? | K32: Operating? | L32: Source
B33: 1100 - Local Property Tax | C33: Direct | D33: 0 | E33: 0 | F33: 0 | G33: 0 | H33: 0 | I33: 0 | M33: 1100
B34: 1900 - Other Local Taxes | C34: Direct | D34: 0 | E34: 0 | F34: 0 | G34: 0 | H34: 0 | I34: 0 | M34: 1900
B35: 1000 - LOCAL TAXES
B36: 2200 - Sale Of Goods, Supplies, & Services - Unassigned | C36: Direct | D36: 6000 | E36: =D36*(1+E$28) -> 6150 | F36: =E36*(1+F$28) -> 6303.75 | G36: =F36*(1+G$28) -> 6461.3437 | H36: =G36*(1+H$28) -> 6622.8773 | I36: =H36*(1+I$28) -> 6788.4493 | J36: Recurring | K36: Operating | L36: State & Local | M36: 2200
B37: 2300 - Investment Earnings | C37: Average Cash on Hand | D37: =AVERAGE('P&L'!D331,'P&L'!D333)*INPUTS!$C$30 -> 37164.3 | J37: Recurring | K37: Non-Operating | L37: State & Local | M37: 2300
B38: 2500 - Gifts Grants, and Donations (Local) | C38: Direct | D38: 0 | E38: =D38*(1+E$28) -> 0 | F38: =E38*(1+F$28) -> 0 | G38: =F38*(1+G$28) -> 0 | H38: =G38*(1+H$28) -> 0 | I38: =H38*(1+I$28) -> 0 | J38: Non-Recurring | K38: Operating | L38: State & Local | M38: 2500
B39: ="All Other "&B40 -> All Other 2000 - LOCAL SUPPORT - NON-TAX | C39: Direct | D39: 0 | E39: =D39*(1+E$28) -> 0 | F39: =E39*(1+F$28) -> 0 | G39: =F39*(1+G$28) -> 0 | H39: =G39*(1+H$28) -> 0 | I39: =H39*(1+I$28) -> 0 | J39: Non-Recurring | K39: Non-Operating | L39: State & Local | M39: 2xxx
B40: 2000 - LOCAL SUPPORT - NON-TAX
B41: 3100 - Basic Education Apportionment (BEA) | C41: Per Pupil | D41: 12613 | E41: =D41*(1+E$26) -> 12928.325 | F41: =E41*(1+F$26) -> 13251.533 | G41: =F41*(1+G$26) -> 13582.821 | H41: =G41*(1+H$26) -> 13922.392 | I41: =H41*(1+I$26) -> 14270.452 | J41: Recurring | K41: Operating | L41: State & Local | M41: 3100
B42: 3121 - Special Education - General Apportionment | C42: Per Pupil - SPED | D42: 455 | E42: =D42*(1+E$26) -> 466.375 | F42: =E42*(1+F$26) -> 478.03437 | G42: =F42*(1+G$26) -> 489.98523 | H42: =G42*(1+H$26) -> 502.23487 | I42: =H42*(1+I$26) -> 514.79074 | J42: Recurring | K42: Operating | L42: State & Local | M42: 3121
B43: ="All Other "&B44 -> All Other 3000 - STATE REVENUE - GENERAL PURPOSE | C43: Direct | D43: 0 | J43: Non-Recurring | K43: Non-Operating | L43: State & Local | M43: 3xxx
B44: 3000 - STATE REVENUE - GENERAL PURPOSE
B45: 4121 - Special Education - State | C45: Per Pupil - SPED | D45: 14631 | E45: =D45*(1+E$26) -> 14996.775 | F45: =E45*(1+F$26) -> 15371.694 | G45: =F45*(1+G$26) -> 15755.987 | H45: =G45*(1+H$26) -> 16149.886 | I45: =H45*(1+I$26) -> 16553.634 | J45: Recurring | K45: Operating | L45: State & Local | M45: 4121
B46: 4155 - Learning Assistance Program (LAP) | C46: Per Pupil | D46: 370 | E46: =D46*(1+E$26) -> 379.25 | F46: =E46*(1+F$26) -> 388.73125 | G46: =F46*(1+G$26) -> 398.44953 | H46: =G46*(1+H$26) -> 408.41077 | I46: =H46*(1+I$26) -> 418.62104 | J46: Recurring | K46: Operating | L46: State & Local | M46: 4155
B47: 4165 - Transitional Bilingual (TBIP) | C47: Per Pupil - EL | D47: 185 | E47: =D47*(1+E$26) -> 189.625 | F47: =E47*(1+F$26) -> 194.36562 | G47: =F47*(1+G$26) -> 199.22477 | H47: =G47*(1+H$26) -> 204.20538 | I47: =H47*(1+I$26) -> 209.31052 | J47: Recurring | K47: Operating | L47: State & Local | M47: 4165
B48: 4174 - Highly Capable | C48: Per Pupil | D48: 32 | E48: =D48*(1+E$26) -> 32.8 | F48: =E48*(1+F$26) -> 33.62 | G48: =F48*(1+G$26) -> 34.4605 | H48: =G48*(1+H$26) -> 35.322012 | I48: =H48*(1+I$26) -> 36.205063 | J48: Recurring | K48: Operating | L48: State & Local | M48: 4174
B49: 4198 - School Food Service | C49: Per Pupil | D49: 23 | E49: =D49*(1+E$26) -> 23.575 | F49: =E49*(1+F$26) -> 24.164375 | G49: =F49*(1+G$26) -> 24.768484 | H49: =G49*(1+H$26) -> 25.387696 | I49: =H49*(1+I$26) -> 26.022389 | J49: Recurring | K49: Operating | L49: State & Local | M49: 4198
B50: 4199 - Transportation - Operations | C50: Per Pupil | D50: 595 | E50: =D50*(1+E$26) -> 609.875 | F50: =E50*(1+F$26) -> 625.12187 | G50: =F50*(1+G$26) -> 640.74992 | H50: =G50*(1+H$26) -> 656.76867 | I50: =H50*(1+I$26) -> 673.18789 | J50: Recurring | K50: Operating | L50: State & Local | M50: 4199
B51: ="All Other "&B52 -> All Other 4000 - STATE REVENUE - SPECIAL PURPOSE | C51: Direct | D51: 0 | E51: 0 | F51: 0 | G51: 0 | H51: 0 | I51: 0 | J51: Non-Recurring | K51: Non-Operating | L51: State & Local | M51: 4xxx
...

Sheet ENROLLMENT
A1: ENROLLMENT INPUTS
A2: ENROLLMENT = Annual Full-Time Equivalent (AAFTE) Enrollment
A3: Washington apportionment is based on average annual full time equivalent (AAFTE) enrollment, not headcount.
A5: Enrollment Demand Guidance
A6: Enrollment demand reflects the market need your school intends to serve. Support your projections with evidence of unmet demand, such as waitlist data, community surveys, feeder school demographics, sibling priority pools, or population growth trends in your catchment area. CSC expects applicants to demonstrate that projected enrollment is achievable rather than merely aspirational.
O9: 0.95 | P9: Sensitivity Analysis % of Planned Enrollment
E10: Planned Enrollment | O10: Sensitivity Analysis
D13: =E10 -> Planned Enrollment | E13: =INPUTS!$D$1 -> 2027 | F13: =INPUTS!$E$1 -> 2028 | G13: =INPUTS!$F$1 -> 2029 | H13: =INPUTS!$G$1 -> 2030 | I13: =INPUTS!$H$1 -> 2031 | J13: =INPUTS!$I$1 -> 2032 | N13: =O10 -> Sensitivity Analysis | O13: =INPUTS!$D$1 -> 2027 | P13: =INPUTS!$E$1 -> 2028 | Q13: =INPUTS!$F$1 -> 2029 | R13: =INPUTS!$G$1 -> 2030 | S13: =INPUTS!$H$1 -> 2031 | T13: =INPUTS!$I$1 -> 2032
D15: CONSOLIDATED ENROLLMENT by SCHOOL | N15: CONSOLIDATED ENROLLMENT by SCHOOL
D16: =INPUTS!C3 -> Cedar Grove Public Schools | E16: =E36 -> 0 | F16: =F36 -> 240 | G16: =G36 -> 480 | H16: =H36 -> 690 | I16: =I36 -> 780 | J16: =J36 -> 780 | N16: =D16 -> Cedar Grove Public Schools | O16: =E16*$O$9 -> 0 | P16: =F16*$O$9 -> 228 | Q16: =G16*$O$9 -> 456 | R16: =H16*$O$9 -> 655.5 | S16: =I16*$O$9 -> 741 | T16: =J16*$O$9 -> 741
D17: Enrollment Total | E17: =SUM(E16:E16) -> 0 | F17: =SUM(F16:F16) -> 240 | G17: =SUM(G16:G16) -> 480 | H17: =SUM(H16:H16) -> 690 | I17: =SUM(I16:I16) -> 780 | J17: =SUM(J16:J16) -> 780 | N17: Enrollment Total | O17: =SUM(O16:O16) -> 0 | P17: =SUM(P16:P16) -> 228 | Q17: =SUM(Q16:Q16) -> 456 | R17: =SUM(R16:R16) -> 655.5 | S17: =SUM(S16:S16) -> 741 | T17: =SUM(T16:T16) -> 741
D18: Year-over-Year Change | F18: =IFERROR((F17-E17)/E17, 0) -> 0 | G18: =IFERROR((G17-F17)/F17, 0) -> 1 | H18: =IFERROR((H17-G17)/G17, 0) -> 0.4375 | I18: =IFERROR((I17-H17)/H17, 0) -> 0.13043478 | J18: =IFERROR((J17-I17)/I17, 0) -> 0 | N18: Year-over-Year Change | P18: =IFERROR((P17-O17)/O17, 0) -> 0 | Q18: =IFERROR((Q17-P17)/P17, 0) -> 1 | R18: =IFERROR((R17-Q17)/Q17, 0) -> 0.4375 | S18: =IFERROR((S17-R17)/R17, 0) -> 0.13043478 | T18: =IFERROR((T17-S17)/S17, 0) -> 0
B20: ENROLLMENT TABLES
B22: =INPUTS!C3 -> Cedar Grove Public Schools | D22: Grade Level | E22: =E$13 -> 2027 | F22: =F$13 -> 2028 | G22: =G$13 -> 2029 | H22: =H$13 -> 2030 | I22: =I$13 -> 2031 | J22: =J$13 -> 2032 | N22: Grade Level | O22: =O$13 -> 2027 | P22: =P$13 -> 2028 | Q22: =Q$13 -> 2029 | R22: =R$13 -> 2030 | S22: =S$13 -> 2031 | T22: =T$13 -> 2032 | U22: =B22 -> Cedar Grove Public Schools
D23: =Drivers!$A$25 -> K | N23: =Drivers!$A$25 -> K | O23: =IFERROR((E23/E$36)*O$16, 0) -> 0 | P23: =(F23/F$36)*P$16 -> 0 | Q23: =(G23/G$36)*Q$16 -> 0 | R23: =(H23/H$36)*R$16 -> 0 | S23: =(I23/I$36)*S$16 -> 0 | T23: =(J23/J$36)*T$16 -> 0
D24: =Drivers!$A$26 -> 1 | N24: =Drivers!$A$26 -> 1 | O24: =IFERROR((E24/E$36)*O$16, 0) -> 0 | P24: =(F24/F$36)*P$16 -> 0 | Q24: =(G24/G$36)*Q$16 -> 0 | R24: =(H24/H$36)*R$16 -> 0 | S24: =(I24/I$36)*S$16 -> 0 | T24: =(J24/J$36)*T$16 -> 0
D25: =Drivers!$A$27 -> 2 | N25: =Drivers!$A$27 -> 2 | O25: =IFERROR((E25/E$36)*O$16, 0) -> 0 | P25: =(F25/F$36)*P$16 -> 0 | Q25: =(G25/G$36)*Q$16 -> 0 | R25: =(H25/H$36)*R$16 -> 0 | S25: =(I25/I$36)*S$16 -> 0 | T25: =(J25/J$36)*T$16 -> 0
B26: Enrollment Data Tool | D26: =Drivers!$A$28 -> 3 | N26: =Drivers!$A$28 -> 3 | O26: =IFERROR((E26/E$36)*O$16, 0) -> 0 | P26: =(F26/F$36)*P$16 -> 0 | Q26: =(G26/G$36)*Q$16 -> 0 | R26: =(H26/H$36)*R$16 -> 0 | S26: =(I26/I$36)*S$16 -> 0 | T26: =(J26/J$36)*T$16 -> 0
B27: *Data Tool Guidance* | D27: =Drivers!$A$29 -> 4 | N27: =Drivers!$A$29 -> 4 | O27: =IFERROR((E27/E$36)*O$16, 0) -> 0 | P27: =(F27/F$36)*P$16 -> 0 | Q27: =(G27/G$36)*Q$16 -> 0 | R27: =(H27/H$36)*R$16 -> 0 | S27: =(I27/I$36)*S$16 -> 0 | T27: =(J27/J$36)*T$16 -> 0
D28: =Drivers!$A$30 -> 5 | N28: =Drivers!$A$30 -> 5 | O28: =IFERROR((E28/E$36)*O$16, 0) -> 0 | P28: =(F28/F$36)*P$16 -> 0 | Q28: =(G28/G$36)*Q$16 -> 0 | R28: =(H28/H$36)*R$16 -> 0 | S28: =(I28/I$36)*S$16 -> 0 | T28: =(J28/J$36)*T$16 -> 0
D29: =Drivers!$A$31 -> 6 | F29: 120 | G29: 120 | H29: 120 | I29: 120 | J29: 120 | N29: =Drivers!$A$31 -> 6 | O29: =IFERROR((E29/E$36)*O$16, 0) -> 0 | P29: =(F29/F$36)*P$16 -> 114 | Q29: =(G29/G$36)*Q$16 -> 114 | R29: =(H29/H$36)*R$16 -> 114 | S29: =(I29/I$36)*S$16 -> 114 | T29: =(J29/J$36)*T$16 -> 114
D30: =Drivers!$A$32 -> 7 | G30: 120 | H30: 120 | I30: 120 | J30: 120 | N30: =Drivers!$A$32 -> 7 | O30: =IFERROR((E30/E$36)*O$16, 0) -> 0 | P30: =(F30/F$36)*P$16 -> 0 | Q30: =(G30/G$36)*Q$16 -> 114 | R30: =(H30/H$36)*R$16 -> 114 | S30: =(I30/I$36)*S$16 -> 114 | T30: =(J30/J$36)*T$16 -> 114
B31: Annual Cohort Attrition | D31: =Drivers!$A$33 -> 8 | H31: 120 | I31: 120 | J31: 120 | N31: =Drivers!$A$33 -> 8 | O31: =IFERROR((E31/E$36)*O$16, 0) -> 0 | P31: =(F31/F$36)*P$16 -> 0 | Q31: =(G31/G$36)*Q$16 -> 0 | R31: =(H31/H$36)*R$16 -> 114 | S31: =(I31/I$36)*S$16 -> 114 | T31: =(J31/J$36)*T$16 -> 114
B32: 0.02 | D32: =Drivers!$A$34 -> 9 | F32: 120 | G32: 120 | H32: 120 | I32: 120 | J32: 120 | N32: =Drivers!$A$34 -> 9 | O32: =IFERROR((E32/E$36)*O$16, 0) -> 0 | P32: =(F32/F$36)*P$16 -> 114 | Q32: =(G32/G$36)*Q$16 -> 114 | R32: =(H32/H$36)*R$16 -> 114 | S32: =(I32/I$36)*S$16 -> 114 | T32: =(J32/J$36)*T$16 -> 114
B33: *Attrition Guidance* | D33: =Drivers!$A$35 -> 10 | G33: 120 | H33: 120 | I33: 120 | J33: 120 | N33: =Drivers!$A$35 -> 10 | O33: =IFERROR((E33/E$36)*O$16, 0) -> 0 | P33: =(F33/F$36)*P$16 -> 0 | Q33: =(G33/G$36)*Q$16 -> 114 | R33: =(H33/H$36)*R$16 -> 114 | S33: =(I33/I$36)*S$16 -> 114 | T33: =(J33/J$36)*T$16 -> 114
D34: =Drivers!$A$36 -> 11 | H34: 90 | I34: 90 | J34: 90 | N34: =Drivers!$A$36 -> 11 | O34: =IFERROR((E34/E$36)*O$16, 0) -> 0 | P34: =(F34/F$36)*P$16 -> 0 | Q34: =(G34/G$36)*Q$16 -> 0 | R34: =(H34/H$36)*R$16 -> 85.5 | S34: =(I34/I$36)*S$16 -> 85.5 | T34: =(J34/J$36)*T$16 -> 85.5
D35: =Drivers!$A$37 -> 12 | I35: 90 | J35: 90 | N35: =Drivers!$A$37 -> 12 | O35: =IFERROR((E35/E$36)*O$16, 0) -> 0 | P35: =(F35/F$36)*P$16 -> 0 | Q35: =(G35/G$36)*Q$16 -> 0 | R35: =(H35/H$36)*R$16 -> 0 | S35: =(I35/I$36)*S$16 -> 85.5 | T35: =(J35/J$36)*T$16 -> 85.5
D36: Enrollment Total | E36: =SUM(E23:E35) -> 0 | F36: =SUM(F23:F35) -> 240 | G36: =SUM(G23:G35) -> 480 | H36: =SUM(H23:H35) -> 690 | I36: =SUM(I23:I35) -> 780 | J36: =SUM(J23:J35) -> 780 | N36: Enrollment Total | O36: =SUM(O23:O35) -> 0 | P36: =SUM(P23:P35) -> 228 | Q36: =SUM(Q23:Q35) -> 456 | R36: =SUM(R23:R35) -> 655.5 | S36: =SUM(S23:S35) -> 741 | T36: =SUM(T23:T35) -> 741
D38: Student Needs Populations | N38: Student Needs Populations | U38: =B22 -> Cedar Grove Public Schools
D39: Funded SPED Enrollment | E39: =MIN(E40,E41)*E36 -> 0 | F39: =MIN(F40,F41)*F36 -> 38.4 | G39: =MIN(G40,G41)*G36 -> 76.8 | H39: =MIN(H40,H41)*H36 -> 110.4 | I39: =MIN(I40,I41)*I36 -> 124.8 | J39: =MIN(J40,J41)*J36 -> 124.8 | N39: SPED Enrollment | O39: =MIN(O40,O41)*O36 -> 0 | P39: =MIN(P40,P41)*P36 -> 36.48 | Q39: =MIN(Q40,Q41)*Q36 -> 72.96 | R39: =MIN(R40,R41)*R36 -> 104.88 | S39: =MIN(S40,S41)*S36 -> 118.56 | T39: =MIN(T40,T41)*T36 -> 118.56
D40: SPED % of Enrollment | E40: 0.16 | F40: 0.16 | G40: 0.16 | H40: 0.16 | I40: 0.16 | J40: 0.16 | N40: SPED % of Enrollment | O40: =E40 -> 0.16 | P40: =F40 -> 0.16 | Q40: =G40 -> 0.16 | R40: =H40 -> 0.16 | S40: =I40 -> 0.16 | T40: =J40 -> 0.16
D41: Funded SPED Enrollment | E41: 0.16 | F41: 0.16 | G41: 0.16 | H41: 0.16 | I41: 0.16 | J41: 0.16 | N41: Funded SPED Enrollment | O41: =E41 -> 0.16 | P41: =F41 -> 0.16 | Q41: =G41 -> 0.16 | R41: =H41 -> 0.16 | S41: =I41 -> 0.16 | T41: =J41 -> 0.16
D42: FRPL Enrollment | E42: =E43*E36 -> 0 | F42: =F43*F36 -> 144 | G42: =G43*G36 -> 288 | H42: =H43*H36 -> 414 | I42: =I43*I36 -> 468 | J42: =J43*J36 -> 468 | N42: FRPL Enrollment | O42: =O41*O36 -> 0 | P42: =P41*P36 -> 36.48 | Q42: =Q41*Q36 -> 72.96 | R42: =R41*R36 -> 104.88 | S42: =S41*S36 -> 118.56 | T42: =T41*T36 -> 118.56
D43: FRPL % of Enrollment | E43: 0.6 | F43: 0.6 | G43: 0.6 | H43: 0.6 | I43: 0.6 | J43: 0.6 | N43: FRPL % of Enrollment | O43: =E43 -> 0.6 | P43: =F43 -> 0.6 | Q43: =G43 -> 0.6 | R43: =H43 -> 0.6 | S43: =I43 -> 0.6 | T43: =J43 -> 0.6
D44: English Learner Enrollment | E44: =E45*E36 -> 0 | F44: =F45*F36 -> 31.2 | G44: =G45*G36 -> 62.4 | H44: =H45*H36 -> 89.7 | I44: =I45*I36 -> 101.4 | J44: =J45*J36 -> 101.4 | N44: English Learner Enrollment | O44: =O43*O38 -> 0 | P44: =P43*P38 -> 0 | Q44: =Q43*Q38 -> 0 | R44: =R43*R38 -> 0 | S44: =S43*S38 -> 0 | T44: =T43*T38 -> 0
D45: EL % of Enrollment | E45: 0.13 | F45: 0.13 | G45: 0.13 | H45: 0.13 | I45: 0.13 | J45: 0.13 | N45: EL % of Enrollment | O45: =E45 -> 0.13 | P45: =F45 -> 0.13 | Q45: =G45 -> 0.13 | R45: =H45 -> 0.13 | S45: =I45 -> 0.13 | T45: =J45 -> 0.13
D46: Elementary Enrollment | E46: =SUM(E23:E28) -> 0 | F46: =SUM(F23:F28) -> 0 | G46: =SUM(G23:G28) -> 0 | H46: =SUM(H23:H28) -> 0 | I46: =SUM(I23:I28) -> 0 | J46: =SUM(J23:J28) -> 0 | N46: Elementary Enrollment | O46: =SUM(O23:O28) -> 0 | P46: =SUM(P23:P28) -> 0 | Q46: =SUM(Q23:Q28) -> 0 | R46: =SUM(R23:R28) -> 0 | S46: =SUM(S23:S28) -> 0 | T46: =SUM(T23:T28) -> 0
D47: Middle School Enrollment | E47: =SUM(E29:E31) -> 0 | F47: =SUM(F29:F31) -> 120 | G47: =SUM(G29:G31) -> 240 | H47: =SUM(H29:H31) -> 360 | I47: =SUM(I29:I31) -> 360 | J47: =SUM(J29:J31) -> 360 | N47: Middle School Enrollment | O47: =SUM(O29:O31) -> 0 | P47: =SUM(P29:P31) -> 114 | Q47: =SUM(Q29:Q31) -> 228 | R47: =SUM(R29:R31) -> 342 | S47: =SUM(S29:S31) -> 342 | T47: =SUM(T29:T31) -> 342
D48: High School Enrollment | E48: =SUM(E32:E35) -> 0 | F48: =SUM(F32:F35) -> 120 | G48: =SUM(G32:G35) -> 240 | H48: =SUM(H32:H35) -> 330 | I48: =SUM(I32:I35) -> 420 | J48: =SUM(J32:J35) -> 420 | N48: High School Enrollment | O48: =SUM(O32:O35) -> 0 | P48: =SUM(P32:P35) -> 114 | Q48: =SUM(Q32:Q35) -> 228 | R48: =SUM(R32:R35) -> 313.5 | S48: =SUM(S32:S35) -> 399 | T48: =SUM(T32:T35) -> 399

Sheet STAFFING
A1: STAFFING
A3: SECTION 1: ACTIVE ENROLLMENT SCENARIO | L3: SECTION 2: AVERAGE SALARIES DATA ---------------->
D5: ENROLLMENT by GRADE | E5: =INPUTS!D1 -> 2027 | F5: =INPUTS!E1 -> 2028 | G5: =INPUTS!F1 -> 2029 | H5: =INPUTS!G1 -> 2030 | I5: =INPUTS!H1 -> 2031 | J5: =INPUTS!I1 -> 2032 | L5: OSPI Financial Reporting - Employee Salary and Benefit Distribution by Category | O5: Guidance to research local average salaries
D6: =ENROLLMENT!D23 -> K | E6: =ENROLLMENT!E23 -> 0 | F6: =ENROLLMENT!F23 -> 0 | G6: =ENROLLMENT!G23 -> 0 | H6: =ENROLLMENT!H23 -> 0 | I6: =ENROLLMENT!I23 -> 0 | J6: =ENROLLMENT!J23 -> 0 | L6: LINK to OSPI Financial Reporting | O6: Average salary estimates are preloaded from three authoritative sources: OSPI Financial Reporting (Washington-specific district salary data by role), the Bureau of Labor Statistics Occupational Employment Survey for Washington State, and Salary.com benchmarks for education-sector roles. Update these estimates based on your school's specific market, geography, and compensation philosophy. Spokane and Eastern WA salaries typically run 10–20% below Seattle metro rates. For roles not yet filled, use the midpoint of your intended hiring range.
D7: =ENROLLMENT!D24 -> 1 | E7: =ENROLLMENT!E24 -> 0 | F7: =ENROLLMENT!F24 -> 0 | G7: =ENROLLMENT!G24 -> 0 | H7: =ENROLLMENT!H24 -> 0 | I7: =ENROLLMENT!I24 -> 0 | J7: =ENROLLMENT!J24 -> 0 | L7: Washington Wage Data
D8: =ENROLLMENT!D25 -> 2 | E8: =ENROLLMENT!E25 -> 0 | F8: =ENROLLMENT!F25 -> 0 | G8: =ENROLLMENT!G25 -> 0 | H8: =ENROLLMENT!H25 -> 0 | I8: =ENROLLMENT!I25 -> 0 | J8: =ENROLLMENT!J25 -> 0 | L8: LINK to Washington Wage Data
D9: =ENROLLMENT!D26 -> 3 | E9: =ENROLLMENT!E26 -> 0 | F9: =ENROLLMENT!F26 -> 0 | G9: =ENROLLMENT!G26 -> 0 | H9: =ENROLLMENT!H26 -> 0 | I9: =ENROLLMENT!I26 -> 0 | J9: =ENROLLMENT!J26 -> 0 | L9: Bureau of Labor Statistics
D10: =ENROLLMENT!D27 -> 4 | E10: =ENROLLMENT!E27 -> 0 | F10: =ENROLLMENT!F27 -> 0 | G10: =ENROLLMENT!G27 -> 0 | H10: =ENROLLMENT!H27 -> 0 | I10: =ENROLLMENT!I27 -> 0 | J10: =ENROLLMENT!J27 -> 0 | L10: LINK to Bureau of Labor Statistics
D11: =ENROLLMENT!D28 -> 5 | E11: =ENROLLMENT!E28 -> 0 | F11: =ENROLLMENT!F28 -> 0 | G11: =ENROLLMENT!G28 -> 0 | H11: =ENROLLMENT!H28 -> 0 | I11: =ENROLLMENT!I28 -> 0 | J11: =ENROLLMENT!J28 -> 0 | M11: 2026
D12: =ENROLLMENT!D29 -> 6 | E12: =ENROLLMENT!E29 -> 0 | F12: =ENROLLMENT!F29 -> 120 | G12: =ENROLLMENT!G29 -> 120 | H12: =ENROLLMENT!H29 -> 120 | I12: =ENROLLMENT!I29 -> 120 | J12: =ENROLLMENT!J29 -> 120 | L12: Position Type | M12: Avg Salary | N12: Average Salaries Research Notes
D13: =ENROLLMENT!D30 -> 7 | E13: =ENROLLMENT!E30 -> 0 | F13: =ENROLLMENT!F30 -> 0 | G13: =ENROLLMENT!G30 -> 120 | H13: =ENROLLMENT!H30 -> 120 | I13: =ENROLLMENT!I30 -> 120 | J13: =ENROLLMENT!J30 -> 120 | L13: =INPUTS!$B$83 -> Chief Executive Officer (CEO)/Executive Director | M13: 200000 | N13: Median of executive education leadership roles; comparable to mid-larger district execs
D14: =ENROLLMENT!D31 -> 8 | E14: =ENROLLMENT!E31 -> 0 | F14: =ENROLLMENT!F31 -> 0 | G14: =ENROLLMENT!G31 -> 0 | H14: =ENROLLMENT!H31 -> 120 | I14: =ENROLLMENT!I31 -> 120 | J14: =ENROLLMENT!J31 -> 120 | L14: =INPUTS!$B$84 -> Principal/Head of School | M14: 130000 | N14: Salary.com / OSPI administrator data
D15: =ENROLLMENT!D32 -> 9 | E15: =ENROLLMENT!E32 -> 0 | F15: =ENROLLMENT!F32 -> 120 | G15: =ENROLLMENT!G32 -> 120 | H15: =ENROLLMENT!H32 -> 120 | I15: =ENROLLMENT!I32 -> 120 | J15: =ENROLLMENT!J32 -> 120 | L15: =INPUTS!$B$85 -> Assistant/Vice Principal | M15: 95000 | N15: ~75–85% of principal comps
D16: =ENROLLMENT!D33 -> 10 | E16: =ENROLLMENT!E33 -> 0 | F16: =ENROLLMENT!F33 -> 0 | G16: =ENROLLMENT!G33 -> 120 | H16: =ENROLLMENT!H33 -> 120 | I16: =ENROLLMENT!I33 -> 120 | J16: =ENROLLMENT!J33 -> 120 | L16: =INPUTS!$B$86 -> Instructional Coach/Curriculum Specialist | M16: 85000 | N16: BLS Instructional Coordinators in WA
D17: =ENROLLMENT!D34 -> 11 | E17: =ENROLLMENT!E34 -> 0 | F17: =ENROLLMENT!F34 -> 0 | G17: =ENROLLMENT!G34 -> 0 | H17: =ENROLLMENT!H34 -> 90 | I17: =ENROLLMENT!I34 -> 90 | J17: =ENROLLMENT!J34 -> 90 | L17: =INPUTS!$B$87 -> Classroom Teacher - Elementary | N17: OSPI teacher salary averages
D18: =ENROLLMENT!D35 -> 12 | E18: =ENROLLMENT!E35 -> 0 | F18: =ENROLLMENT!F35 -> 0 | G18: =ENROLLMENT!G35 -> 0 | H18: =ENROLLMENT!H35 -> 0 | I18: =ENROLLMENT!I35 -> 90 | J18: =ENROLLMENT!J35 -> 90 | L18: =INPUTS!$B$88 -> Classroom Teacher - Middle School | M18: 70000 | N18: Slight lift for content specialization
D19: Enrollment Total | E19: =SUM(E6:E18) -> 0 | F19: =SUM(F6:F18) -> 240 | G19: =SUM(G6:G18) -> 480 | H19: =SUM(H6:H18) -> 690 | I19: =SUM(I6:I18) -> 780 | J19: =SUM(J6:J18) -> 780 | L19: =INPUTS!$B$89 -> Classroom Teacher - High School | M19: 70000 | N19: Reflects content exp & credential expectations
L20: =INPUTS!$B$90 -> Special Education (SPED) Teacher | M20: 85000 | N20: SPED teacher premium vs general teacher
D21: SPECIAL EDUCATION ENROLLMENT | L21: =INPUTS!$B$91 -> English Learner (EL) Specialist | M21: 80000 | N21: BLS ESL / specialist teacher proxy
D22: =INPUTS!$C$3 -> Cedar Grove Public Schools | E22: =CHOOSE(INPUTS!$D$17, ENROLLMENT!E$39, ENROLLMENT!O$39) -> 0 | F22: =CHOOSE(INPUTS!$D$17, ENROLLMENT!F$39, ENROLLMENT!P$39) -> 38.4 | G22: =CHOOSE(INPUTS!$D$17, ENROLLMENT!G$39, ENROLLMENT!Q$39) -> 76.8 | H22: =CHOOSE(INPUTS!$D$17, ENROLLMENT!H$39, ENROLLMENT!R$39) -> 110.4 | I22: =CHOOSE(INPUTS!$D$17, ENROLLMENT!I$39, ENROLLMENT!S$39) -> 124.8 | J22: =CHOOSE(INPUTS!$D$17, ENROLLMENT!J$39, ENROLLMENT!T$39) -> 124.8 | L22: =INPUTS!$B$92 -> Intervention Specialist (Reading/Math) | M22: 68000 | N22: Comparable to teacher pay
L23: =INPUTS!$B$93 -> Instructional Aides/Paraeducators | M23: 40000 | N23: OSPI paraeducators data
D24: ENGLISH LEARNER ENROLLMENT | L24: =INPUTS!$B$94 -> School Counselor | M24: 75000 | N24: BLS school counselor occupation
D25: =INPUTS!$C$3 -> Cedar Grove Public Schools | E25: =CHOOSE(INPUTS!$D$17, ENROLLMENT!E$44, ENROLLMENT!O$44) -> 0 | F25: =CHOOSE(INPUTS!$D$17, ENROLLMENT!F$44, ENROLLMENT!P$44) -> 31.2 | G25: =CHOOSE(INPUTS!$D$17, ENROLLMENT!G$44, ENROLLMENT!Q$44) -> 62.4 | H25: =CHOOSE(INPUTS!$D$17, ENROLLMENT!H$44, ENROLLMENT!R$44) -> 89.7 | I25: =CHOOSE(INPUTS!$D$17, ENROLLMENT!I$44, ENROLLMENT!S$44) -> 101.4 | J25: =CHOOSE(INPUTS!$D$17, ENROLLMENT!J$44, ENROLLMENT!T$44) -> 101.4 | L25: =INPUTS!$B$95 -> School Psychologist | M25: 85000 | N25: BLS WA psychologist wage
L26: =INPUTS!$B$96 -> Registrar/Enrollment Manager | M26: 60000 | N26: Office / school admin support wage
D27: ELEMENTARY ENROLLMENT | L27: =INPUTS!$B$97 -> Chief Operations Officer (COO)/Ops. Manager | M27: 160000 | N27: BLS operations managers
D28: =INPUTS!$C$3 -> Cedar Grove Public Schools | E28: =CHOOSE(INPUTS!$D$17, ENROLLMENT!E$46, ENROLLMENT!O$46) -> 0 | F28: =CHOOSE(INPUTS!$D$17, ENROLLMENT!F$46, ENROLLMENT!P$46) -> 0 | G28: =CHOOSE(INPUTS!$D$17, ENROLLMENT!G$46, ENROLLMENT!Q$46) -> 0 | H28: =CHOOSE(INPUTS!$D$17, ENROLLMENT!H$46, ENROLLMENT!R$46) -> 0 | I28: =CHOOSE(INPUTS!$D$17, ENROLLMENT!I$46, ENROLLMENT!S$46) -> 0 | J28: =CHOOSE(INPUTS!$D$17, ENROLLMENT!J$46, ENROLLMENT!T$46) -> 0 | L28: =INPUTS!$B$98 -> CFO/Finance Manager/Business Manager | M28: 140000 | N28: BLS financial managers
L29: =INPUTS!$B$99 -> Administrative Assistant/Office Manager | M29: 68000 | N29: BLS office admin support
D30: MIDDLE SCHOOL ENROLLMENT | L30: =INPUTS!$B$100 -> Human Resources Specialist | M30: 68000 | N30: BLS HR specialist
D31: =INPUTS!$C$3 -> Cedar Grove Public Schools | E31: =CHOOSE(INPUTS!$D$17, ENROLLMENT!E$47, ENROLLMENT!O$47) -> 0 | F31: =CHOOSE(INPUTS!$D$17, ENROLLMENT!F$47, ENROLLMENT!P$47) -> 120 | G31: =CHOOSE(INPUTS!$D$17, ENROLLMENT!G$47, ENROLLMENT!Q$47) -> 240 | H31: =CHOOSE(INPUTS!$D$17, ENROLLMENT!H$47, ENROLLMENT!R$47) -> 360 | I31: =CHOOSE(INPUTS!$D$17, ENROLLMENT!I$47, ENROLLMENT!S$47) -> 360 | J31: =CHOOSE(INPUTS!$D$17, ENROLLMENT!J$47, ENROLLMENT!T$47) -> 360 | L31: =INPUTS!$B$101 -> IT Coordinator/Instructional Technologist | M31: 80000 | N31: BLS IT support specialist
L32: =INPUTS!$B$102 -> Facilities Manager | M32: 70000 | N32: BLS facilities manager
D33: HIGH SCHOOL ENROLLMENT | L33: =INPUTS!$B$103 -> Custodian/Facilities Maintenance | M33: 42000 | N33: BLS custodial maintenance
D34: =INPUTS!$C$3 -> Cedar Grove Public Schools | E34: =CHOOSE(INPUTS!$D$17, ENROLLMENT!E$48, ENROLLMENT!O$48) -> 0 | F34: =CHOOSE(INPUTS!$D$17, ENROLLMENT!F$48, ENROLLMENT!P$48) -> 120 | G34: =CHOOSE(INPUTS!$D$17, ENROLLMENT!G$48, ENROLLMENT!Q$48) -> 240 | H34: =CHOOSE(INPUTS!$D$17, ENROLLMENT!H$48, ENROLLMENT!R$48) -> 330 | I34: =CHOOSE(INPUTS!$D$17, ENROLLMENT!I$48, ENROLLMENT!S$48) -> 420 | J34: =CHOOSE(INPUTS!$D$17, ENROLLMENT!J$48, ENROLLMENT!T$48) -> 420 | L34: =INPUTS!$B$104 -> Security/Safety Coordinator | M34: 50000 | N34: Protective services occupational group in WA
L35: =INPUTS!$B$105 -> Nutrition Program Manager/Lead | M35: 60000 | N35: Food service leadership proxy
L36: =INPUTS!$B$106 -> Food Service Staff (Cooks/Servers) | M36: 30000 | N36: BLS food prep & service wage
L37: =INPUTS!$B$107 -> Transportation Coordinator | M37: 60000 | N37: Midpoint admin / transport lead
L38: =INPUTS!$B$108 -> Substitute Teacher Pool | M38: 30000 | N38: Based on substitute daily rates * utilization
L39: =INPUTS!$B$109 -> Nurse | M39: 65000 | N39: Salary.com / OSPI administrator data
L40: =INPUTS!$B$110 -> Librarian | M40: 62000 | N40: Salary.com / OSPI administrator data
L41: =INPUTS!$B$111 -> Manager of Student Support | M41: 68000
L42: =INPUTS!$B$112 -> College & Athletics Director | M42: 68000
...

Sheet DEBT
B4: INPUTS | P4: =B6 -> Modeled Borrowing
B6: Modeled Borrowing | J6: Initial Transaction | R6: =C8 -> 5175000 | S6: Par Amount
B7: Sources: | F7: Uses: | J7: Interest | K7: Term | L7: Amortization | Q7: =J8 -> 0.05 | R7: =Q7/12 -> 0.0041666667 | S7: Rate (Annual ➜ Monthly)
B8: Total Financing | C8: =C11-SUM(C10:C10) -> 5175000 | D8: 1 | F8: Project Cost | G8: 5000000 | H8: =G8/$G$11 -> 0.96618357 | J8: 0.05 | K8: 30 | L8: 30 | Q8: =L8 -> 30 | R8: =Q8*12 -> 360 | S8: Amortization (Years ➜ Months)
F9: Contingency | K9: Years | L9: Years
F10: Est. Cost of Issuance | G10: =SUM(G8:G9)*H10 -> 175000 | H10: 0.035
B11: Total Sources | C11: =G11 -> 5175000 | D11: 1 | F11: Total Uses | G11: =SUM(G8:G10) -> 5175000 | H11: =SUM(H8:H10) -> 1.0011836
T12: =EDATE(K14, R8) -> 57526 | U12: Maturity Date
B13: Depreciation Summary | F13: Depreciable Term | Q13: =EOMONTH(K14, 1) -> 46599 | R13: First Interest Payment Date | T13: {=INDEX(V57:V447, _xlfn.XMATCH(TRUE, V57:V447<>"",,-1))} -> 2.4301698e-09 | U13: Balance at Maturity
B14: Capitalized Borrowing: | C14: =SUM(G8:G10) -> 5175000 | F14: 30 | G14: Years | K14: 46568 | L14: Closing Date | Q14: =EOMONTH(K14, 1) -> 46599 | R14: First Principal Payment Date
B15: Annual Depreciation: | C15: =C14/F14 -> 172500 | K15: =YEAR(K14) -> 2027 | L15: Closing Year
P16: 2025 | U16: Model Time Horizon
P18: FY | Q18: Year End | R18: Principal | S18: Interest Expense | T18: Total Pmt | U18: Beg Bal | V18: End Bal
P19: 2026 | Q19: =DATE(VALUE(P19),6,30) -> 46203 | R19: =SUMIFS(R$57:R$447,$Q$57:$Q$447, ">="&$P16, $Q$57:$Q$447, "<="&$Q19) -> 0 | S19: =SUMIFS(S$57:S$447,$Q$57:$Q$447, ">="&$P16, $Q$57:$Q$447, "<="&$Q19) -> 0 | T19: =R19+S19 -> 0 | U19: =R6 -> 5175000 | V19: =U19 -> 5175000
P20: =P19+1 -> 2027 | Q20: =EDATE(Q19, 12) -> 46568 | R20: =SUMIFS(R$57:R$447,$Q$57:$Q$447, ">"&$Q19, $Q$57:$Q$447, "<="&$Q20) -> 0 | S20: =SUMIFS(S$57:S$447,$Q$57:$Q$447, ">"&$Q19, $Q$57:$Q$447, "<="&$Q20) -> 0 | T20: =R20+S20 -> 0 | U20: =U19 -> 5175000 | V20: =IFERROR(INDEX($V$57:$V$447, MATCH(Q20,$Q$57:$Q$447, 0), 1), 0) -> 0
P21: =P20+1 -> 2028 | Q21: =EDATE(Q20, 12) -> 46934 | R21: =SUMIFS(R$57:R$447,$Q$57:$Q$447, ">"&$Q20, $Q$57:$Q$447, "<="&$Q21) -> 76350.157 | S21: =SUMIFS(S$57:S$447,$Q$57:$Q$447, ">"&$Q20, $Q$57:$Q$447, "<="&$Q21) -> 257016.07 | T21: =R21+S21 -> 333366.23 | U21: =V20 -> 0 | V21: =IFERROR(INDEX($V$57:$V$447, MATCH(Q21,$Q$57:$Q$447, 0), 1), 0) -> 5098649.8
P22: =P21+1 -> 2029 | Q22: =EDATE(Q21, 12) -> 47299 | R22: =SUMIFS(R$57:R$447,$Q$57:$Q$447, ">"&$Q21, $Q$57:$Q$447, "<="&$Q22) -> 80256.376 | S22: =SUMIFS(S$57:S$447,$Q$57:$Q$447, ">"&$Q21, $Q$57:$Q$447, "<="&$Q22) -> 253109.85 | T22: =R22+S22 -> 333366.23 | U22: =V21 -> 5098649.8 | V22: =IFERROR(INDEX($V$57:$V$447, MATCH(Q22,$Q$57:$Q$447, 0), 1), 0) -> 5018393.5
P23: =P22+1 -> 2030 | Q23: =EDATE(Q22, 12) -> 47664 | R23: =SUMIFS(R$57:R$447,$Q$57:$Q$447, ">"&$Q22, $Q$57:$Q$447, "<="&$Q23) -> 84362.444 | S23: =SUMIFS(S$57:S$447,$Q$57:$Q$447, ">"&$Q22, $Q$57:$Q$447, "<="&$Q23) -> 249003.78 | T23: =R23+S23 -> 333366.23 | U23: =V22 -> 5018393.5 | V23: =IFERROR(INDEX($V$57:$V$447, MATCH(Q23,$Q$57:$Q$447, 0), 1), 0) -> 4934031
P24: =P23+1 -> 2031 | Q24: =EDATE(Q23, 12) -> 48029 | R24: =SUMIFS(R$57:R$447,$Q$57:$Q$447, ">"&$Q23, $Q$57:$Q$447, "<="&$Q24) -> 88678.587 | S24: =SUMIFS(S$57:S$447,$Q$57:$Q$447, ">"&$Q23, $Q$57:$Q$447, "<="&$Q24) -> 244687.64 | T24: =R24+S24 -> 333366.23 | U24: =V23 -> 4934031 | V24: =IFERROR(INDEX($V$57:$V$447, MATCH(Q24,$Q$57:$Q$447, 0), 1), 0) -> 4845352.4
P25: =P24+1 -> 2032 | Q25: =EDATE(Q24, 12) -> 48395 | R25: =SUMIFS(R$57:R$447,$Q$57:$Q$447, ">"&$Q24, $Q$57:$Q$447, "<="&$Q25) -> 93215.552 | S25: =SUMIFS(S$57:S$447,$Q$57:$Q$447, ">"&$Q24, $Q$57:$Q$447, "<="&$Q25) -> 240150.68 | T25: =R25+S25 -> 333366.23 | U25: =V24 -> 4845352.4 | V25: =IFERROR(INDEX($V$57:$V$447, MATCH(Q25,$Q$57:$Q$447, 0), 1), 0) -> 4752136.9
P26: =P25+1 -> 2033 | Q26: =EDATE(Q25, 12) -> 48760 | R26: =SUMIFS(R$57:R$447,$Q$57:$Q$447, ">"&$Q25, $Q$57:$Q$447, "<="&$Q26) -> 97984.636 | S26: =SUMIFS(S$57:S$447,$Q$57:$Q$447, ">"&$Q25, $Q$57:$Q$447, "<="&$Q26) -> 235381.59 | T26: =R26+S26 -> 333366.23 | U26: =V25 -> 4752136.9 | V26: =IFERROR(INDEX($V$57:$V$447, MATCH(Q26,$Q$57:$Q$447, 0), 1), 0) -> 4654152.2
P27: =P26+1 -> 2034 | Q27: =EDATE(Q26, 12) -> 49125 | R27: =SUMIFS(R$57:R$447,$Q$57:$Q$447, ">"&$Q26, $Q$57:$Q$447, "<="&$Q27) -> 102997.72 | S27: =SUMIFS(S$57:S$447,$Q$57:$Q$447, ">"&$Q26, $Q$57:$Q$447, "<="&$Q27) -> 230368.51 | T27: =R27+S27 -> 333366.23 | U27: =V26 -> 4654152.2 | V27: =IFERROR(INDEX($V$57:$V$447, MATCH(Q27,$Q$57:$Q$447, 0), 1), 0) -> 4551154.5
P28: =P27+1 -> 2035 | Q28: =EDATE(Q27, 12) -> 49490 | R28: =SUMIFS(R$57:R$447,$Q$57:$Q$447, ">"&$Q27, $Q$57:$Q$447, "<="&$Q28) -> 108267.27 | S28: =SUMIFS(S$57:S$447,$Q$57:$Q$447, ">"&$Q27, $Q$57:$Q$447, "<="&$Q28) -> 225098.95 | T28: =R28+S28 -> 333366.23 | U28: =V27 -> 4551154.5 | V28: =IFERROR(INDEX($V$57:$V$447, MATCH(Q28,$Q$57:$Q$447, 0), 1), 0) -> 4442887.3
P29: =P28+1 -> 2036 | Q29: =EDATE(Q28, 12) -> 49856 | R29: =SUMIFS(R$57:R$447,$Q$57:$Q$447, ">"&$Q28, $Q$57:$Q$447, "<="&$Q29) -> 113806.43 | S29: =SUMIFS(S$57:S$447,$Q$57:$Q$447, ">"&$Q28, $Q$57:$Q$447, "<="&$Q29) -> 219559.79 | T29: =R29+S29 -> 333366.23 | U29: =V28 -> 4442887.3 | V29: =IFERROR(INDEX($V$57:$V$447, MATCH(Q29,$Q$57:$Q$447, 0), 1), 0) -> 4329080.8
P30: =P29+1 -> 2037 | Q30: =EDATE(Q29, 12) -> 50221 | R30: =SUMIFS(R$57:R$447,$Q$57:$Q$447, ">"&$Q29, $Q$57:$Q$447, "<="&$Q30) -> 119628.99 | S30: =SUMIFS(S$57:S$447,$Q$57:$Q$447, ">"&$Q29, $Q$57:$Q$447, "<="&$Q30) -> 213737.24 | T30: =R30+S30 -> 333366.23 | U30: =V29 -> 4329080.8 | V30: =IFERROR(INDEX($V$57:$V$447, MATCH(Q30,$Q$57:$Q$447, 0), 1), 0) -> 4209451.8
P31: =P30+1 -> 2038 | Q31: =EDATE(Q30, 12) -> 50586 | R31: =SUMIFS(R$57:R$447,$Q$57:$Q$447, ">"&$Q30, $Q$57:$Q$447, "<="&$Q31) -> 125749.43 | S31: =SUMIFS(S$57:S$447,$Q$57:$Q$447, ">"&$Q30, $Q$57:$Q$447, "<="&$Q31) -> 207616.79 | T31: =R31+S31 -> 333366.23 | U31: =V30 -> 4209451.8 | V31: =IFERROR(INDEX($V$57:$V$447, MATCH(Q31,$Q$57:$Q$447, 0), 1), 0) -> 4083702.4
P32: =P31+1 -> 2039 | Q32: =EDATE(Q31, 12) -> 50951 | R32: =SUMIFS(R$57:R$447,$Q$57:$Q$447, ">"&$Q31, $Q$57:$Q$447, "<="&$Q32) -> 132183.01 | S32: =SUMIFS(S$57:S$447,$Q$57:$Q$447, ">"&$Q31, $Q$57:$Q$447, "<="&$Q32) -> 201183.22 | T32: =R32+S32 -> 333366.23 | U32: =V31 -> 4083702.4 | V32: =IFERROR(INDEX($V$57:$V$447, MATCH(Q32,$Q$57:$Q$447, 0), 1), 0) -> 3951519.4
... P54: =P53+1 -> 2061 | Q54: =EDATE(Q53, 12) -> 58987 | R54: =SUMIFS(R$57:R$447,$Q$57:$Q$447, ">"&$Q53, $Q$57:$Q$447, "<="&$Q54) -> 0 | S54: =SUMIFS(S$57:S$447,$Q$57:$Q$447, ">"&$Q53, $Q$57:$Q$447, "<="&$Q54) -> 0 | T54: =R54+S54 -> 0 | U54: =V53 -> 0 | V54: =IFERROR(INDEX($V$57:$V$447, MATCH(Q54,$Q$57:$Q$447, 0), 1), 0) -> 0
R55: =SUM(R19:R54) -> 5175000 | S55: =SUM(S19:S54) -> 4825986.8 | T55: =SUM(T19:T54) -> 10000987
P56: Month | Q56: Date | R56: Principal | S56: Interest | T56: Total Pmt | U56: Beg Bal | V56: End Bal
P57: =IF(Q57<Q$14, 0, 1) -> 1 | Q57: =EOMONTH(K14, 1) -> 46599 | R57: =IF(OR(Q57<Q$14, Q57>T$12),0, -IF(P57=0, 0, PPMT(R$7, P57, R$8, R$6))) -> 6218.019 | S57: =IF(OR(Q57<Q$13, Q57>T$12), 0, +U57*R$7) -> 21562.5 | T57: =R57+S57 -> 27780.519 | U57: =R6 -> 5175000 | V57: =IF(Q57>T$12, "", +U57-R57) -> 5168782
P58: =IF(Q58<Q$14, 0, P57+1) -> 2 | Q58: =EOMONTH(Q57, 1) -> 46630 | R58: =IF(OR(Q58<Q$14, Q58>T$12),0, -IF(P58=0, 0, PPMT(R$7, P58, R$8, R$6))) -> 6243.9274 | S58: =IF(OR(Q58<Q$13, Q58>T$12), 0, +U58*R$7) -> 21536.592 | T58: =R58+S58 -> 27780.519 | U58: =IF(Q58>T$12, 0, +V57) -> 5168782 | V58: =IF(Q58>T$12, "", +U58-R58) -> 5162538.1
P59: =IF(Q59<Q$14, 0, P58+1) -> 3 | Q59: =EOMONTH(Q58, 1) -> 46660 | R59: =IF(OR(Q59<Q$14, Q59>T$12),0, -IF(P59=0, 0, PPMT(R$7, P59, R$8, R$6))) -> 6269.9438 | S59: =IF(OR(Q59<Q$13, Q59>T$12), 0, +U59*R$7) -> 21510.575 | T59: =R59+S59 -> 27780.519 | U59: =IF(Q59>T$12, 0, +V58) -> 5162538.1 | V59: =IF(Q59>T$12, "", +U59-R59) -> 5156268.1
P60: =IF(Q60<Q$14, 0, P59+1) -> 4 | Q60: =EOMONTH(Q59, 1) -> 46691 | R60: =IF(OR(Q60<Q$14, Q60>T$12),0, -IF(P60=0, 0, PPMT(R$7, P60, R$8, R$6))) -> 6296.0685 | S60: =IF(OR(Q60<Q$13, Q60>T$12), 0, +U60*R$7) -> 21484.45 | T60: =R60+S60 -> 27780.519 | U60: =IF(Q60>T$12, 0, +V59) -> 5156268.1 | V60: =IF(Q60>T$12, "", +U60-R60) -> 5149972
P61: =IF(Q61<Q$14, 0, P60+1) -> 5 | Q61: =EOMONTH(Q60, 1) -> 46721 | R61: =IF(OR(Q61<Q$14, Q61>T$12),0, -IF(P61=0, 0, PPMT(R$7, P61, R$8, R$6))) -> 6322.3022 | S61: =IF(OR(Q61<Q$13, Q61>T$12), 0, +U61*R$7) -> 21458.217 | T61: =R61+S61 -> 27780.519 | U61: =IF(Q61>T$12, 0, +V60) -> 5149972 | V61: =IF(Q61>T$12, "", +U61-R61) -> 5143649.7
P62: =IF(Q62<Q$14, 0, P61+1) -> 6 | Q62: =EOMONTH(Q61, 1) -> 46752 | R62: =IF(OR(Q62<Q$14, Q62>T$12),0, -IF(P62=0, 0, PPMT(R$7, P62, R$8, R$6))) -> 6348.6451 | S62: =IF(OR(Q62<Q$13, Q62>T$12), 0, +U62*R$7) -> 21431.874 | T62: =R62+S62 -> 27780.519 | U62: =IF(Q62>T$12, 0, +V61) -> 5143649.7 | V62: =IF(Q62>T$12, "", +U62-R62) -> 5137301.1
P63: =IF(Q63<Q$14, 0, P62+1) -> 7 | Q63: =EOMONTH(Q62, 1) -> 46783 | R63: =IF(OR(Q63<Q$14, Q63>T$12),0, -IF(P63=0, 0, PPMT(R$7, P63, R$8, R$6))) -> 6375.0978 | S63: =IF(OR(Q63<Q$13, Q63>T$12), 0, +U63*R$7) -> 21405.421 | T63: =R63+S63 -> 27780.519 | U63: =IF(Q63>T$12, 0, +V62) -> 5137301.1 | V63: =IF(Q63>T$12, "", +U63-R63) -> 5130926
P64: =IF(Q64<Q$14, 0, P63+1) -> 8 | Q64: =EOMONTH(Q63, 1) -> 46812 | R64: =IF(OR(Q64<Q$14, Q64>T$12),0, -IF(P64=0, 0, PPMT(R$7, P64, R$8, R$6))) -> 6401.6607 | S64: =IF(OR(Q64<Q$13, Q64>T$12), 0, +U64*R$7) -> 21378.858 | T64: =R64+S64 -> 27780.519 | U64: =IF(Q64>T$12, 0, +V63) -> 5130926 | V64: =IF(Q64>T$12, "", +U64-R64) -> 5124524.3
P65: =IF(Q65<Q$14, 0, P64+1) -> 9 | Q65: =EOMONTH(Q64, 1) -> 46843 | R65: =IF(OR(Q65<Q$14, Q65>T$12),0, -IF(P65=0, 0, PPMT(R$7, P65, R$8, R$6))) -> 6428.3343 | S65: =IF(OR(Q65<Q$13, Q65>T$12), 0, +U65*R$7) -> 21352.185 | T65: =R65+S65 -> 27780.519 | U65: =IF(Q65>T$12, 0, +V64) -> 5124524.3 | V65: =IF(Q65>T$12, "", +U65-R65) -> 5118096
P66: =IF(Q66<Q$14, 0, P65+1) -> 10 | Q66: =EOMONTH(Q65, 1) -> 46873 | R66: =IF(OR(Q66<Q$14, Q66>T$12),0, -IF(P66=0, 0, PPMT(R$7, P66, R$8, R$6))) -> 6455.119 | S66: =IF(OR(Q66<Q$13, Q66>T$12), 0, +U66*R$7) -> 21325.4 | T66: =R66+S66 -> 27780.519 | U66: =IF(Q66>T$12, 0, +V65) -> 5118096 | V66: =IF(Q66>T$12, "", +U66-R66) -> 5111640.9
...

Sheet P&L
A1: WA Charter School - Draft P&L (Operating Statement) | D1: =INPUTS!D1 -> 2027 | E1: =INPUTS!E1 -> 2028 | F1: =INPUTS!F1 -> 2029 | G1: =INPUTS!G1 -> 2030 | H1: =INPUTS!H1 -> 2031 | I1: =INPUTS!I1 -> 2032
A3: SECTION 1: DASHBOARD
D5: =$D$1 -> 2027 | E5: =$E$1 -> 2028 | F5: =$F$1 -> 2029 | G5: =$G$1 -> 2030 | H5: =$H$1 -> 2031 | I5: =$I$1 -> 2032
C6: Enrollment & Staffing
C7: Enrollment | D7: =D57 -> 0 | E7: =E57 -> 240 | F7: =F57 -> 480 | G7: =G57 -> 690 | H7: =H57 -> 780 | I7: =I57 -> 780
C8: Full-Time Employment (FTE) Count | D8: =D108 -> 1 | E8: =E108 -> 27.25 | F8: =F108 -> 49.25 | G8: =G108 -> 71.25 | H8: =H108 -> 83.25 | I8: =I108 -> 83.25
C9: Students / FTE | D9: =IFERROR(D57/D108, 0) -> 0 | E9: =IFERROR(E57/E108, 0) -> 8.8073394 | F9: =IFERROR(F57/F108, 0) -> 9.7461929 | G9: =IFERROR(G57/G108, 0) -> 9.6842105 | H9: =IFERROR(H57/H108, 0) -> 9.3693694 | I9: =IFERROR(I57/I108, 0) -> 9.3693694
C10: Bottomline Metrics
C11: Operating Margin | D11: =IFERROR(D296/#REF!, 0) -> 0 | E11: =IFERROR(E296/#REF!, 0) -> 0 | F11: =IFERROR(F296/#REF!, 0) -> 0 | G11: =IFERROR(G296/#REF!, 0) -> 0 | H11: =IFERROR(H296/#REF!, 0) -> 0 | I11: =IFERROR(I296/#REF!, 0) -> 0
C12: Surplus/Deficit on Total Revenue | D12: =IFERROR(D296, 0) -> -22380 | E12: =IFERROR(E296, 0) -> 45975.525 | F12: =IFERROR(F296, 0) -> 817917.6 | G12: =IFERROR(G296, 0) -> 1462166.8 | H12: =IFERROR(H296, 0) -> 1564760.8 | I12: =IFERROR(I296, 0) -> 1881269.9
C13: Surplus/Deficit on Recurring Revenue | D13: =IFERROR(D169-#REF!, 0) -> 0 | E13: =IFERROR(E169-#REF!, 0) -> 0 | F13: =IFERROR(F169-#REF!, 0) -> 0 | G13: =IFERROR(G169-#REF!, 0) -> 0 | H13: =IFERROR(H169-#REF!, 0) -> 0 | I13: =IFERROR(I169-#REF!, 0) -> 0
C14: Surplus/Deficit per Pupil on Total Revenue | D14: =IFERROR(D12/D7, 0) -> 0 | E14: =IFERROR(E12/E7, 0) -> 191.56469 | F14: =IFERROR(F12/F7, 0) -> 1703.995 | G14: =IFERROR(G12/G7, 0) -> 2119.0823 | H14: =IFERROR(H12/H7, 0) -> 2006.1036 | I14: =IFERROR(I12/I7, 0) -> 2411.8845
C15: Revenue Metrics
C16: Total Revenue | D16: =D164 -> 256000 | E16: =E164 -> 5089873.9 | F16: =F164 -> 9531906.8 | G16: =G164 -> 13632355 | H16: =H164 -> 15652037 | I16: =I164 -> 16014494
C17: Total Operating Revenue | D17: =D173 -> 6000 | E17: =E173 -> 4789873.9 | F17: =F173 -> 9231906.8 | G17: =G173 -> 13332355 | H17: =H173 -> 15352037 | I17: =I173 -> 15714494
C18: Total Non-Operating Revenue | D18: =D174 -> 250000 | E18: =E174 -> 300000 | F18: =F174 -> 300000 | G18: =G174 -> 300000 | H18: =H174 -> 300000 | I18: =I174 -> 300000
C19: Total Revenue per Pupil | D19: =IFERROR(D16/D7, 0) -> 0 | E19: =IFERROR(E16/E7, 0) -> 21207.808 | F19: =IFERROR(F16/F7, 0) -> 19858.139 | G19: =IFERROR(G16/G7, 0) -> 19757.037 | H19: =IFERROR(H16/H7, 0) -> 20066.714 | I19: =IFERROR(I16/I7, 0) -> 20531.403
C20: Recurring Revenue per Pupil | D20: =IFERROR(D169/D7, 0) -> 0 | E20: =IFERROR(E169/E7, 0) -> 19957.808 | F20: =IFERROR(F169/F7, 0) -> 19233.139 | G20: =IFERROR(G169/G7, 0) -> 19322.254 | H20: =IFERROR(H169/H7, 0) -> 19682.099 | I20: =IFERROR(I169/I7, 0) -> 20146.787
C21: Non-Recurring Revenue per Student | D21: =IFERROR(D170/D7, 0) -> 0 | E21: =IFERROR(E170/E7, 0) -> 1250 | F21: =IFERROR(F170/F7, 0) -> 625 | G21: =IFERROR(G170/G7, 0) -> 434.78261 | H21: =IFERROR(H170/H7, 0) -> 384.61538 | I21: =IFERROR(I170/I7, 0) -> 384.61538
C22: Expense Metrics
C23: Total Expenses | D23: =IFERROR(D275, 0) -> 278380 | E23: =IFERROR(E275, 0) -> 5043898.3 | F23: =IFERROR(F275, 0) -> 8713989.2 | G23: =IFERROR(G275, 0) -> 12170189 | H23: =IFERROR(H275, 0) -> 14087276 | I23: =IFERROR(I275, 0) -> 14133224
C24: Total Expense per Pupil | D24: =IFERROR(D23/D7, 0) -> 0 | E24: =IFERROR(E23/E7, 0) -> 21016.243 | F24: =IFERROR(F23/F7, 0) -> 18154.144 | G24: =IFERROR(G23/G7, 0) -> 17637.954 | H24: =IFERROR(H23/H7, 0) -> 18060.61 | I24: =IFERROR(I23/I7, 0) -> 18119.518
C25: Personnel Expense per Pupil (Total Comp.) | D25: =IFERROR(D280/D7, 0) -> 0 | E25: =IFERROR(E280/E7, 0) -> 11467.224 | F25: =IFERROR(F280/F7, 0) -> 10248.641 | G25: =IFERROR(G280/G7, 0) -> 10388.446 | H25: =IFERROR(H280/H7, 0) -> 11011.172 | I25: =IFERROR(I280/I7, 0) -> 11341.507
C26: Non-Personnel Expense per Pupil | D26: =IFERROR( SUM(D281:D285) / D7, 0) -> 0 | E26: =IFERROR( SUM(E281:E285) / E7, 0) -> 9549.0192 | F26: =IFERROR( SUM(F281:F285) / F7, 0) -> 7905.5031 | G26: =IFERROR( SUM(G281:G285) / G7, 0) -> 7249.5081 | H26: =IFERROR( SUM(H281:H285) / H7, 0) -> 7049.4388 | I26: =IFERROR( SUM(I281:I285) / I7, 0) -> 6778.0116
C27: Sustainability Percentages
C28: Recurring Revenue as % of Total Expenses | D28: =IFERROR(D169/D23, 0) -> 0.021553273 | E28: =IFERROR(E169/E23, 0) -> 0.94963727 | F28: =IFERROR(F169/F23, 0) -> 1.0594352 | G28: =IFERROR(G169/G23, 0) -> 1.0954929 | H28: =IFERROR(H169/H23, 0) -> 1.0897804 | I28: =IFERROR(I169/I23, 0) -> 1.1118832
C29: Total Compensation as % of Recurring Revenue | D29: =IFERROR(D280/D169, 0) -> 44.633333 | E29: =IFERROR(E280/E169, 0) -> 0.57457332 | F29: =IFERROR(F280/F169, 0) -> 0.53286367 | G29: =IFERROR(G280/G169, 0) -> 0.53764153 | H29: =IFERROR(H280/H169, 0) -> 0.55945109 | I29: =IFERROR(I280/I169, 0) -> 0.56294368
C30: Facilities Expense as % of Recurring Revenue | D30: =IFERROR(D282/D169, 0) -> 0 | E30: =IFERROR(E282/E169, 0) -> 0.085179696 | F30: =IFERROR(F282/F169, 0) -> 0.055568152 | G30: =IFERROR(G282/G169, 0) -> 0.038477822 | H30: =IFERROR(H282/H169, 0) -> 0.033415761 | I30: =IFERROR(I282/I169, 0) -> 0.032645021
C31: All Other Expenses as % of Recurring Revenue | D31: =IFERROR(SUM(D281,D283:D285)/D169, 0) -> 1.7633333 | E31: =IFERROR(SUM(E281,E283:E285)/E169, 0) -> 0.39328063 | F31: =IFERROR(SUM(F281,F283:F285)/F169, 0) -> 0.35546735 | G31: =IFERROR(SUM(G281,G283:G285)/G169, 0) -> 0.33671174 | H31: =IFERROR(SUM(H281,H283:H285)/H169, 0) -> 0.32474924 | I31: =IFERROR(SUM(I281,I283:I285)/I169, 0) -> 0.30378637
C32: Cash and Debt Management
C33: DCOH | D33: =D335 -> 91.982069 | E33: =E335 -> 102.63112 | F33: =F335 -> 97.426326 | G33: =G335 -> 116.52469 | H33: =H335 -> 143.71482 | I33: =I335 -> 194.50007
C34: Total Philanthropy Assumed for 60 DCOH | D34: =MAX(D343,D361)+SUM(D124,D155) -> 272380 | E34: =MAX(E343,E361)+SUM(E124,E155) -> 300000 | F34: =MAX(F343,F361)+SUM(F124,F155) -> 300000 | G34: =MAX(G343,G361)+SUM(G124,G155) -> 300000 | H34: =MAX(H343,H361)+SUM(H124,H155) -> 300000 | I34: =MAX(I343,I361)+SUM(I124,I155) -> 300000
C35: Assumed Philanthropy Received Per Pupil | D35: =IFERROR(D34/D7, 0) -> 0 | E35: =IFERROR(E34/E7, 0) -> 1250 | F35: =IFERROR(F34/F7, 0) -> 625 | G35: =IFERROR(G34/G7, 0) -> 434.78261 | H35: =IFERROR(H34/H7, 0) -> 384.61538 | I35: =IFERROR(I34/I7, 0) -> 384.61538
C36: DCOH w/Assumed Philanthropy | D36: =MAX(D341:D342)/((E328-E303)/365) -> 91.982069 | E36: =MAX(E341:E342)/((E328-E303)/365) -> 102.63112 | F36: =MAX(F341:F342)/((F328-F303)/365) -> 97.426326 | G36: =MAX(G341:G342)/((G328-G303)/365) -> 116.52469 | H36: =MAX(H341:H342)/((H328-H303)/365) -> 143.71482 | I36: =MAX(I341:I342)/((I328-I303)/365) -> 194.50007
C37: Additional Philanthropy required for 60 DCOH | D37: =D343 -> 0 | E37: =E343 -> 0 | F37: =F343 -> 0 | G37: =G343 -> 0 | H37: =H343 -> 0 | I37: =I343 -> 0
C38: DSCR | D38: =D355 -> NA | E38: =E355 -> 1.9294205 | F38: =F355 -> 3.4593614 | G38: =G355 -> 4.8893802 | H38: =H355 -> 5.1879887 | I38: =I355 -> 5.9811925
C39: Additional Philanthropy required for 1.2x DSCR | D39: =D361 -> 22380 | E39: =E361 -> 0 | F39: =F361 -> 0 | G39: =G361 -> 0 | H39: =H361 -> 0 | I39: =I361 -> 0
A41: SECTION 2: ENROLLMENT SUMMARY
C43: Enrollment by Grade | D43: =D$1 -> 2027 | E43: =E$1 -> 2028 | F43: =F$1 -> 2029 | G43: =G$1 -> 2030 | H43: =H$1 -> 2031 | I43: =I$1 -> 2032
C44: K | D44: =CHOOSE(INPUTS!$D$17, ENROLLMENT!E23,ENROLLMENT!O23) -> 0 | E44: =CHOOSE(INPUTS!$D$17, ENROLLMENT!F23,ENROLLMENT!P23) -> 0 | F44: =CHOOSE(INPUTS!$D$17, ENROLLMENT!G23,ENROLLMENT!Q23) -> 0 | G44: =CHOOSE(INPUTS!$D$17, ENROLLMENT!H23,ENROLLMENT!R23) -> 0 | H44: =CHOOSE(INPUTS!$D$17, ENROLLMENT!I23,ENROLLMENT!S23) -> 0 | I44: =CHOOSE(INPUTS!$D$17, ENROLLMENT!J23,ENROLLMENT!T23) -> 0
...

Sheet Cash
A1: YEAR ONE CASH FLOW FORECAST | D1: Sep MTD | E1: Oct MTD | F1: Nov MTD | G1: Dec MTD | H1: Jan MTD | I1: Feb MTD | J1: Mar MTD | K1: Apr MTD | L1: May MTD | M1: Jun MTD | N1: Jul MTD | O1: Aug MTD
B3: Year 1 Starting Cash | D3: ACTUAL (ACT) or FORECAST (FCAST)
B4: ='P&L'!E331 -> 1227620 | D4: FCAST | E4: FCAST | F4: FCAST | G4: FCAST | H4: FCAST | I4: FCAST | J4: FCAST | K4: FCAST | L4: FCAST | M4: FCAST | N4: FCAST | O4: FCAST
B5: Minimum DCOH | D5: =IF(D$4="ACT",1,0) -> 0 | E5: =IF(E$4="ACT",1,0) -> 0 | F5: =IF(F$4="ACT",1,0) -> 0 | G5: =IF(G$4="ACT",1,0) -> 0 | H5: =IF(H$4="ACT",1,0) -> 0 | I5: =IF(I$4="ACT",1,0) -> 0 | J5: =IF(J$4="ACT",1,0) -> 0 | K5: =IF(K$4="ACT",1,0) -> 0 | ... O5: =IF(O$4="ACT",1,0) -> 0
B6: 45
D7: Sep MTD | E7: Oct MTD | F7: Nov MTD | G7: Dec MTD | H7: Jan MTD | I7: Feb MTD | J7: Mar MTD | K7: Apr MTD | L7: May MTD | M7: Jun MTD | N7: Jul MTD | O7: Aug MTD | P7: Total
C9: Cash on Hand (Beginning) | D9: =B4 -> 1227620 | E9: =D11 -> 1318652.4 | F9: =E11 -> 1230663.1 | G9: =F11 -> 1075708.1 | H9: =G11 -> 1078889.9 | I9: =H11 -> 1062304.6 | J9: =I11 -> 1207336.3 | K9: =J11 -> 1210518.1 | L9: =K11 -> 1213699.9 | ... O9: =N11 -> 1153134.3 | P9: =D9 -> 1227620
C11: Cash on Hand (Ending) | D11: =SUM(D9,D97) -> 1318652.4 | E11: =SUM(E9,E97) -> 1230663.1 | F11: =SUM(F9,F97) -> 1075708.1 | G11: =SUM(G9,G97) -> 1078889.9 | H11: =SUM(H9,H97) -> 1062304.6 | I11: =SUM(I9,I97) -> 1207336.3 | J11: =SUM(J9,J97) -> 1210518.1 | K11: =SUM(K9,K97) -> 1213699.9 | ... P11: =SUM(P9,P97) -> 1361732.9
C13: Days of Cash on Hand | D13: =D11/(('P&L'!$E275-'P&L'!$E272)/365) -> 98.802868 | E13: =E11/(('P&L'!$E275-'P&L'!$E272)/365) -> 92.210081 | F13: =F11/(('P&L'!$E275-'P&L'!$E272)/365) -> 80.599744 | G13: =G11/(('P&L'!$E275-'P&L'!$E272)/365) -> 80.838146 | H13: =H11/(('P&L'!$E275-'P&L'!$E272)/365) -> 79.595455 | I13: =I11/(('P&L'!$E275-'P&L'!$E272)/365) -> 90.462273 | J13: =J11/(('P&L'!$E275-'P&L'!$E272)/365) -> 90.700674 | K13: =K11/(('P&L'!$E275-'P&L'!$E272)/365) -> 90.939075 | ... O13: =O11/(('P&L'!$E275-'P&L'!$E272)/365) -> 102.03077
B15: Distribution | C15: Cash Receipts
A16: Revenues | B16: 10-Month Academic Calendar | C16: ='P&L'!C122 -> 2200 - Sale Of Goods, Supplies, & Services - Unassigned | D16: {=_xlfn.IFS($B16="12-Month Smoothing", 'P&L'!$E122*Drivers!G$113, $B16="10-Month Academic Calendar", 'P&L'!$E122*Drivers!G$114, $B16="Quarterly Smoothing", 'P&L'!$E122*Drivers!G$115, $B16="Two-Installment (front-loaded)", 'P&L'!$E122*Drivers!G$116, $B16="Two-Installment (back-loaded)", 'P&L'!$E122*Drivers!G$117, $B16="Year Start Lump Sum", 'P&L'!$E122*Drivers!G$118,$B16="OSPI State Apportionment", 'P&L'!$E122*Drivers!G$119, $B16="Expense Reimbursement", 'P&L'!$E122*Drivers!G$120, $B16="Direct Monthly Input", 0)} -> 615 | E16: {=_xlfn.IFS($B16="12-Month Smoothing", 'P&L'!$E122*Drivers!H$113, $B16="10-Month Academic Calendar", 'P&L'!$E122*Drivers!H$114, $B16="Quarterly Smoothing", 'P&L'!$E122*Drivers!H$115, $B16="Two-Installment (front-loaded)", 'P&L'!$E122*Drivers!H$116, $B16="Two-Installment (back-loaded)", 'P&L'!$E122*Drivers!H$117, $B16="Year Start Lump Sum", 'P&L'!$E122*Drivers!H$118,$B16="OSPI State Apportionment", 'P&L'!$E122*Drivers!H$119, $B16="Expense Reimbursement", 'P&L'!$E122*Drivers!H$120, $B16="Direct Monthly Input", 0)} -> 615 | F16: {=_xlfn.IFS($B16="12-Month Smoothing", 'P&L'!$E122*Drivers!I$113, $B16="10-Month Academic Calendar", 'P&L'!$E122*Drivers!I$114, $B16="Quarterly Smoothing", 'P&L'!$E122*Drivers!I$115, $B16="Two-Installment (front-loaded)", 'P&L'!$E122*Drivers!I$116, $B16="Two-Installment (back-loaded)", 'P&L'!$E122*Drivers!I$117, $B16="Year Start Lump Sum", 'P&L'!$E122*Drivers!I$118,$B16="OSPI State Apportionment", 'P&L'!$E122*Drivers!I$119, $B16="Expense Reimbursement", 'P&L'!$E122*Drivers!I$120, $B16="Direct Monthly Input", 0)} -> 615 | G16: {=_xlfn.IFS($B16="12-Month Smoothing", 'P&L'!$E122*Drivers!J$113, $B16="10-Month Academic Calendar", 'P&L'!$E122*Drivers!J$114, $B16="Quarterly Smoothing", 'P&L'!$E122*Drivers!J$115, $B16="Two-Installment (front-loaded)", 'P&L'!$E122*Drivers!J$116, $B16="Two-Installment (back-loaded)", 'P&L'!$E122*Drivers!J$117, $B16="Year Start Lump Sum", 'P&L'!$E122*Drivers!J$118,$B16="OSPI State Apportionment", 'P&L'!$E122*Drivers!J$119, $B16="Expense Reimbursement", 'P&L'!$E122*Drivers!J$120, $B16="Direct Monthly Input", 0)} -> 615 | H16: {=_xlfn.IFS($B16="12-Month Smoothing", 'P&L'!$E122*Drivers!K$113, $B16="10-Month Academic Calendar", 'P&L'!$E122*Drivers!K$114, $B16="Quarterly Smoothing", 'P&L'!$E122*Drivers!K$115, $B16="Two-Installment (front-loaded)", 'P&L'!$E122*Drivers!K$116, $B16="Two-Installment (back-loaded)", 'P&L'!$E122*Drivers!K$117, $B16="Year Start Lump Sum", 'P&L'!$E122*Drivers!K$118,$B16="OSPI State Apportionment", 'P&L'!$E122*Drivers!K$119, $B16="Expense Reimbursement", 'P&L'!$E122*Drivers!K$120, $B16="Direct Monthly Input", 0)} -> 615 | I16: {=_xlfn.IFS($B16="12-Month Smoothing", 'P&L'!$E122*Drivers!L$113, $B16="10-Month Academic Calendar", 'P&L'!$E122*Drivers!L$114, $B16="Quarterly Smoothing", 'P&L'!$E122*Drivers!L$115, $B16="Two-Installment (front-loaded)", 'P&L'!$E122*Drivers!L$116, $B16="Two-Installment (back-loaded)", 'P&L'!$E122*Drivers!L$117, $B16="Year Start Lump Sum", 'P&L'!$E122*Drivers!L$118,$B16="OSPI State Apportionment", 'P&L'!$E122*Drivers!L$119, $B16="Expense Reimbursement", 'P&L'!$E122*Drivers!L$120, $B16="Direct Monthly Input", 0)} -> 615 | J16: {=_xlfn.IFS($B16="12-Month Smoothing", 'P&L'!$E122*Drivers!M$113, $B16="10-Month Academic Calendar", 'P&L'!$E122*Drivers!M$114, $B16="Quarterly Smoothing", 'P&L'!$E122*Drivers!M$115, $B16="Two-Installment (front-loaded)", 'P&L'!$E122*Drivers!M$116, $B16="Two-Installment (back-loaded)", 'P&L'!$E122*Drivers!M$117, $B16="Year Start Lump Sum", 'P&L'!$E122*Drivers!M$118,$B16="OSPI State Apportionment", 'P&L'!$E122*Drivers!M$119, $B16="Expense Reimbursement", 'P&L'!$E122*Drivers!M$120, $B16="Direct Monthly Input", 0)} -> 615 | K16: {=_xlfn.IFS($B16="12-Month Smoothing", 'P&L'!$E122*Drivers!N$113, $B16="10-Month Academic Calendar", 'P&L'!$E122*Drivers!N$114, $B16="Quarterly Smoothing", 'P&L'!$E122*Drivers!N$115, $B16="Two-Installment (front-loaded)", 'P&L'!$E122*Drivers!N$116, $B16="Two-Installment (back-loaded)", 'P&L'!$E122*Drivers!N$117, $B16="Year Start Lump Sum", 'P&L'!$E122*Drivers!N$118,$B16="OSPI State Apportionment", 'P&L'!$E122*Drivers!N$119, $B16="Expense Reimbursement", 'P&L'!$E122*Drivers!N$120, $B16="Direct Monthly Input", 0)} -> 615 | ... O16: {=_xlfn.IFS($B16="12-Month Smoothing", 'P&L'!$E122*Drivers!R$113, $B16="10-Month Academic Calendar", 'P&L'!$E122*Drivers!R$114, $B16="Quarterly Smoothing", 'P&L'!$E122*Drivers!R$115, $B16="Two-Installment (front-loaded)", 'P&L'!$E122*Drivers!R$116, $B16="Two-Installment (back-loaded)", 'P&L'!$E122*Drivers!R$117, $B16="Year Start Lump Sum", 'P&L'!$E122*Drivers!R$118,$B16="OSPI State Apportionment", 'P&L'!$E122*Drivers!R$119, $B16="Expense Reimbursement", 'P&L'!$E122*Drivers!R$120, $B16="Direct Monthly Input", 0)} -> 0 | P16: =SUM(D16:O16) -> 6150
